  0%|          | 0/16 [00:00<?, ?it/s]  6%|6         | 1/16 [01:02<15:40, 62.67s/it] 12%|#2        | 2/16 [03:27<20:23, 87.41s/it] 19%|#8        | 3/16 [04:31<17:23, 80.23s/it] 25%|##5       | 4/16 [05:41<15:24, 77.08s/it] 31%|###1      | 5/16 [08:11<18:11, 99.23s/it] 38%|###7      | 6/16 [09:12<14:36, 87.61s/it] 44%|####3     | 7/16 [10:09<11:46, 78.53s/it] 50%|#####     | 8/16 [11:05<09:34, 71.77s/it] 56%|#####6    | 9/16 [12:11<08:10, 70.05s/it]  0%|          | 0/15 [00:00<?, ?it/s]  7%|6         | 1/15 [01:06<15:31, 66.52s/it] 13%|#3        | 2/15 [02:44<16:26, 75.85s/it] 20%|##        | 3/15 [04:07<15:37, 78.15s/it] 27%|##6       | 4/15 [05:41<15:09, 82.71s/it] 33%|###3      | 5/15 [07:04<13:48, 82.88s/it] 40%|####      | 6/15 [08:24<12:18, 82.09s/it] 47%|####6     | 7/15 [09:44<10:50, 81.33s/it] 53%|#####3    | 8/15 [11:02<09:22, 80.39s/it] 60%|######    | 9/15 [12:39<08:33, 85.56s/it]  0%|          | 0/11 [00:00<?, ?it/s]  9%|9         | 1/11 [01:24<14:01, 84.19s/it] 18%|#8        | 2/11 [02:37<12:07, 80.83s/it] 27%|##7       | 3/11 [03:50<10:28, 78.55s/it] 36%|###6      | 4/11 [04:55<08:40, 74.37s/it]./picks.sh: line 2: 58061 Terminated: 15          /Users/rohannarain/anaconda3/bin/python retrieve_data.py
./picks.sh: line 2: 59695 Terminated: 15          /Users/rohannarain/anaconda3/bin/python retrieve_data.py
./picks.sh: line 2: 86963 Terminated: 15          /Users/rohannarain/anaconda3/bin/python retrieve_data.py
2019-08-23 14:25:00.755 python[88140:1800557] _LSScheduleNotificationFunction() failed on line 649 in function id scheduleApplicationNotification(LSNotificationCode, NSWorkspaceNotificationCenter *)
2019-08-23 14:25:00.756 python[88139:1800556] _LSScheduleNotificationFunction() failed on line 649 in function id scheduleApplicationNotification(LSNotificationCode, NSWorkspaceNotificationCenter *)
2019-08-23 14:25:00.765 python[88138:1800553] _LSScheduleNotificationFunction() failed on line 649 in function id scheduleApplicationNotification(LSNotificationCode, NSWorkspaceNotificationCenter *)
  0%|          | 0/14 [00:00<?, ?it/s]  7%|7         | 1/14 [01:29<19:26, 89.70s/it] 14%|#4        | 2/14 [03:02<18:05, 90.49s/it] 21%|##1       | 3/14 [04:47<17:25, 95.02s/it] 29%|##8       | 4/14 [06:29<16:10, 97.05s/it] 36%|###5      | 5/14 [08:07<14:35, 97.30s/it] 43%|####2     | 6/14 [09:51<13:14, 99.31s/it] 50%|#####     | 7/14 [11:40<11:56, 102.36s/it] 57%|#####7    | 8/14 [13:39<10:43, 107.26s/it] 64%|######4   | 9/14 [15:11<08:33, 102.71s/it] 71%|#######1  | 10/14 [16:50<06:46, 101.54s/it]Traceback (most recent call last):
  File "/Users/rohannarain/anaconda3/lib/python3.6/site-packages/requests/packages/urllib3/connectionpool.py", line 594, in urlopen
    chunked=chunked)
  File "/Users/rohannarain/anaconda3/lib/python3.6/site-packages/requests/packages/urllib3/connectionpool.py", line 391, in _make_request
    six.raise_from(e, None)
  File "<string>", line 2, in raise_from
  File "/Users/rohannarain/anaconda3/lib/python3.6/site-packages/requests/packages/urllib3/connectionpool.py", line 387, in _make_request
    httplib_response = conn.getresponse()
  File "/Users/rohannarain/anaconda3/lib/python3.6/http/client.py", line 1331, in getresponse
    response.begin()
  File "/Users/rohannarain/anaconda3/lib/python3.6/http/client.py", line 297, in begin
    version, status, reason = self._read_status()
  File "/Users/rohannarain/anaconda3/lib/python3.6/http/client.py", line 266, in _read_status
    raise RemoteDisconnected("Remote end closed connection without"
http.client.RemoteDisconnected: Remote end closed connection without response

During handling of the above exception, another exception occurred:

Traceback (most recent call last):
  File "/Users/rohannarain/anaconda3/lib/python3.6/site-packages/requests/adapters.py", line 423, in send
    timeout=timeout
  File "/Users/rohannarain/anaconda3/lib/python3.6/site-packages/requests/packages/urllib3/connectionpool.py", line 643, in urlopen
    _stacktrace=sys.exc_info()[2])
  File "/Users/rohannarain/anaconda3/lib/python3.6/site-packages/requests/packages/urllib3/util/retry.py", line 334, in increment
    raise six.reraise(type(error), error, _stacktrace)
  File "/Users/rohannarain/anaconda3/lib/python3.6/site-packages/requests/packages/urllib3/packages/six.py", line 685, in reraise
    raise value.with_traceback(tb)
  File "/Users/rohannarain/anaconda3/lib/python3.6/site-packages/requests/packages/urllib3/connectionpool.py", line 594, in urlopen
    chunked=chunked)
  File "/Users/rohannarain/anaconda3/lib/python3.6/site-packages/requests/packages/urllib3/connectionpool.py", line 391, in _make_request
    six.raise_from(e, None)
  File "<string>", line 2, in raise_from
  File "/Users/rohannarain/anaconda3/lib/python3.6/site-packages/requests/packages/urllib3/connectionpool.py", line 387, in _make_request
    httplib_response = conn.getresponse()
  File "/Users/rohannarain/anaconda3/lib/python3.6/http/client.py", line 1331, in getresponse
    response.begin()
  File "/Users/rohannarain/anaconda3/lib/python3.6/http/client.py", line 297, in begin
    version, status, reason = self._read_status()
  File "/Users/rohannarain/anaconda3/lib/python3.6/http/client.py", line 266, in _read_status
    raise RemoteDisconnected("Remote end closed connection without"
requests.packages.urllib3.exceptions.ProtocolError: ('Connection aborted.', RemoteDisconnected('Remote end closed connection without response',))

During handling of the above exception, another exception occurred:

Traceback (most recent call last):
  File "retrieve_data.py", line 472, in <module>
    generate_hits_data()
  File "retrieve_data.py", line 408, in generate_hits_data
    player_id = get_player_id_from_name(player)
  File "retrieve_data.py", line 50, in get_player_id_from_name
    return statsapi.lookup_player(player_name)[0]['id']
  File "/Users/rohannarain/anaconda3/lib/python3.6/site-packages/statsapi/__init__.py", line 933, in lookup_player
    r = get('sports_players',params)
  File "/Users/rohannarain/anaconda3/lib/python3.6/site-packages/statsapi/__init__.py", line 1421, in get
    r = requests.get(url)
  File "/Users/rohannarain/anaconda3/lib/python3.6/site-packages/requests/api.py", line 70, in get
    return request('get', url, params=params, **kwargs)
  File "/Users/rohannarain/anaconda3/lib/python3.6/site-packages/requests/api.py", line 56, in request
    return session.request(method=method, url=url, **kwargs)
  File "/Users/rohannarain/anaconda3/lib/python3.6/site-packages/requests/sessions.py", line 488, in request
    resp = self.send(prep, **send_kwargs)
  File "/Users/rohannarain/anaconda3/lib/python3.6/site-packages/requests/sessions.py", line 609, in send
    r = adapter.send(request, **kwargs)
  File "/Users/rohannarain/anaconda3/lib/python3.6/site-packages/requests/adapters.py", line 473, in send
    raise ConnectionError(err, request=request)
requests.exceptions.ConnectionError: ('Connection aborted.', RemoteDisconnected('Remote end closed connection without response',))

Getting data...
Traceback (most recent call last):
  File "train_model.py", line 37, in <module>
    hits_test = pd.read_csv("data/player_stats/player_stats_{}.csv".format(today))
  File "/Users/rohannarain/anaconda3/lib/python3.6/site-packages/pandas/io/parsers.py", line 678, in parser_f
    return _read(filepath_or_buffer, kwds)
  File "/Users/rohannarain/anaconda3/lib/python3.6/site-packages/pandas/io/parsers.py", line 440, in _read
    parser = TextFileReader(filepath_or_buffer, **kwds)
  File "/Users/rohannarain/anaconda3/lib/python3.6/site-packages/pandas/io/parsers.py", line 787, in __init__
    self._make_engine(self.engine)
  File "/Users/rohannarain/anaconda3/lib/python3.6/site-packages/pandas/io/parsers.py", line 1014, in _make_engine
    self._engine = CParserWrapper(self.f, **self.options)
  File "/Users/rohannarain/anaconda3/lib/python3.6/site-packages/pandas/io/parsers.py", line 1708, in __init__
    self._reader = parsers.TextReader(src, **kwds)
  File "pandas/_libs/parsers.pyx", line 384, in pandas._libs.parsers.TextReader.__cinit__
  File "pandas/_libs/parsers.pyx", line 695, in pandas._libs.parsers.TextReader._setup_parser_source
FileNotFoundError: File b'data/player_stats/player_stats_08_24_2019.csv' does not exist
